{
 "cells": [
  {
   "cell_type": "code",
   "execution_count": 6,
   "metadata": {},
   "outputs": [
    {
     "data": {
      "text/html": [
       "\n",
       "        <iframe\n",
       "            width=\"100%\"\n",
       "            height=\"650\"\n",
       "            src=\"http://127.0.0.1:8060/\"\n",
       "            frameborder=\"0\"\n",
       "            allowfullscreen\n",
       "            \n",
       "        ></iframe>\n",
       "        "
      ],
      "text/plain": [
       "<IPython.lib.display.IFrame at 0x2310836a410>"
      ]
     },
     "metadata": {},
     "output_type": "display_data"
    },
    {
     "name": "stderr",
     "output_type": "stream",
     "text": [
      "[2024-07-12 00:22:03,880] ERROR in app: Exception on /_dash-update-component [POST]\n",
      "Traceback (most recent call last):\n",
      "  File \"c:\\Users\\plmar\\anaconda3\\Lib\\site-packages\\flask\\app.py\", line 2525, in wsgi_app\n",
      "    response = self.full_dispatch_request()\n",
      "               ^^^^^^^^^^^^^^^^^^^^^^^^^^^^\n",
      "  File \"c:\\Users\\plmar\\anaconda3\\Lib\\site-packages\\flask\\app.py\", line 1822, in full_dispatch_request\n",
      "    rv = self.handle_user_exception(e)\n",
      "         ^^^^^^^^^^^^^^^^^^^^^^^^^^^^^\n",
      "  File \"c:\\Users\\plmar\\anaconda3\\Lib\\site-packages\\flask\\app.py\", line 1820, in full_dispatch_request\n",
      "    rv = self.dispatch_request()\n",
      "         ^^^^^^^^^^^^^^^^^^^^^^^\n",
      "  File \"c:\\Users\\plmar\\anaconda3\\Lib\\site-packages\\flask\\app.py\", line 1796, in dispatch_request\n",
      "    return self.ensure_sync(self.view_functions[rule.endpoint])(**view_args)\n",
      "           ^^^^^^^^^^^^^^^^^^^^^^^^^^^^^^^^^^^^^^^^^^^^^^^^^^^^^^^^^^^^^^^^^\n",
      "  File \"c:\\Users\\plmar\\anaconda3\\Lib\\site-packages\\dash\\dash.py\", line 1310, in dispatch\n",
      "    ctx.run(\n",
      "  File \"c:\\Users\\plmar\\anaconda3\\Lib\\site-packages\\dash\\_callback.py\", line 442, in add_context\n",
      "    output_value = func(*func_args, **func_kwargs)  # %% callback invoked %%\n",
      "                   ^^^^^^^^^^^^^^^^^^^^^^^^^^^^^^^\n",
      "  File \"C:\\Users\\plmar\\AppData\\Local\\Temp\\ipykernel_88144\\1684445943.py\", line 78, in update_result\n",
      "    ymin = df.loc[relOut['xaxis.range'][1]:relOut['xaxis.range'][0],'y'].min()\n",
      "                  ~~~~~~^^^^^^^^^^^^^^^\n",
      "TypeError: 'NoneType' object is not subscriptable\n",
      "[2024-07-12 00:22:04,122] ERROR in app: Exception on /_dash-update-component [POST]\n",
      "Traceback (most recent call last):\n",
      "  File \"c:\\Users\\plmar\\anaconda3\\Lib\\site-packages\\flask\\app.py\", line 2525, in wsgi_app\n",
      "    response = self.full_dispatch_request()\n",
      "               ^^^^^^^^^^^^^^^^^^^^^^^^^^^^\n",
      "  File \"c:\\Users\\plmar\\anaconda3\\Lib\\site-packages\\flask\\app.py\", line 1822, in full_dispatch_request\n",
      "    rv = self.handle_user_exception(e)\n",
      "         ^^^^^^^^^^^^^^^^^^^^^^^^^^^^^\n",
      "  File \"c:\\Users\\plmar\\anaconda3\\Lib\\site-packages\\flask\\app.py\", line 1820, in full_dispatch_request\n",
      "    rv = self.dispatch_request()\n",
      "         ^^^^^^^^^^^^^^^^^^^^^^^\n",
      "  File \"c:\\Users\\plmar\\anaconda3\\Lib\\site-packages\\flask\\app.py\", line 1796, in dispatch_request\n",
      "    return self.ensure_sync(self.view_functions[rule.endpoint])(**view_args)\n",
      "           ^^^^^^^^^^^^^^^^^^^^^^^^^^^^^^^^^^^^^^^^^^^^^^^^^^^^^^^^^^^^^^^^^\n",
      "  File \"c:\\Users\\plmar\\anaconda3\\Lib\\site-packages\\dash\\dash.py\", line 1310, in dispatch\n",
      "    ctx.run(\n",
      "  File \"c:\\Users\\plmar\\anaconda3\\Lib\\site-packages\\dash\\_callback.py\", line 442, in add_context\n",
      "    output_value = func(*func_args, **func_kwargs)  # %% callback invoked %%\n",
      "                   ^^^^^^^^^^^^^^^^^^^^^^^^^^^^^^^\n",
      "  File \"C:\\Users\\plmar\\AppData\\Local\\Temp\\ipykernel_88144\\1684445943.py\", line 78, in update_result\n",
      "    ymin = df.loc[relOut['xaxis.range'][1]:relOut['xaxis.range'][0],'y'].min()\n",
      "                  ~~~~~~^^^^^^^^^^^^^^^\n",
      "KeyError: 'xaxis.range'\n",
      "[2024-07-12 00:22:07,026] ERROR in app: Exception on /_dash-update-component [POST]\n",
      "Traceback (most recent call last):\n",
      "  File \"c:\\Users\\plmar\\anaconda3\\Lib\\site-packages\\flask\\app.py\", line 2525, in wsgi_app\n",
      "    response = self.full_dispatch_request()\n",
      "               ^^^^^^^^^^^^^^^^^^^^^^^^^^^^\n",
      "  File \"c:\\Users\\plmar\\anaconda3\\Lib\\site-packages\\flask\\app.py\", line 1822, in full_dispatch_request\n",
      "    rv = self.handle_user_exception(e)\n",
      "         ^^^^^^^^^^^^^^^^^^^^^^^^^^^^^\n",
      "  File \"c:\\Users\\plmar\\anaconda3\\Lib\\site-packages\\flask\\app.py\", line 1820, in full_dispatch_request\n",
      "    rv = self.dispatch_request()\n",
      "         ^^^^^^^^^^^^^^^^^^^^^^^\n",
      "  File \"c:\\Users\\plmar\\anaconda3\\Lib\\site-packages\\flask\\app.py\", line 1796, in dispatch_request\n",
      "    return self.ensure_sync(self.view_functions[rule.endpoint])(**view_args)\n",
      "           ^^^^^^^^^^^^^^^^^^^^^^^^^^^^^^^^^^^^^^^^^^^^^^^^^^^^^^^^^^^^^^^^^\n",
      "  File \"c:\\Users\\plmar\\anaconda3\\Lib\\site-packages\\dash\\dash.py\", line 1310, in dispatch\n",
      "    ctx.run(\n",
      "  File \"c:\\Users\\plmar\\anaconda3\\Lib\\site-packages\\dash\\_callback.py\", line 442, in add_context\n",
      "    output_value = func(*func_args, **func_kwargs)  # %% callback invoked %%\n",
      "                   ^^^^^^^^^^^^^^^^^^^^^^^^^^^^^^^\n",
      "  File \"C:\\Users\\plmar\\AppData\\Local\\Temp\\ipykernel_88144\\1684445943.py\", line 78, in update_result\n",
      "    ymin = df.loc[relOut['xaxis.range'][1]:relOut['xaxis.range'][0],'y'].min()\n",
      "                  ~~~~~~^^^^^^^^^^^^^^^\n",
      "KeyError: 'xaxis.range'\n",
      "[2024-07-12 00:22:08,183] ERROR in app: Exception on /_dash-update-component [POST]\n",
      "Traceback (most recent call last):\n",
      "  File \"c:\\Users\\plmar\\anaconda3\\Lib\\site-packages\\flask\\app.py\", line 2525, in wsgi_app\n",
      "    response = self.full_dispatch_request()\n",
      "               ^^^^^^^^^^^^^^^^^^^^^^^^^^^^\n",
      "  File \"c:\\Users\\plmar\\anaconda3\\Lib\\site-packages\\flask\\app.py\", line 1822, in full_dispatch_request\n",
      "    rv = self.handle_user_exception(e)\n",
      "         ^^^^^^^^^^^^^^^^^^^^^^^^^^^^^\n",
      "  File \"c:\\Users\\plmar\\anaconda3\\Lib\\site-packages\\flask\\app.py\", line 1820, in full_dispatch_request\n",
      "    rv = self.dispatch_request()\n",
      "         ^^^^^^^^^^^^^^^^^^^^^^^\n",
      "  File \"c:\\Users\\plmar\\anaconda3\\Lib\\site-packages\\flask\\app.py\", line 1796, in dispatch_request\n",
      "    return self.ensure_sync(self.view_functions[rule.endpoint])(**view_args)\n",
      "           ^^^^^^^^^^^^^^^^^^^^^^^^^^^^^^^^^^^^^^^^^^^^^^^^^^^^^^^^^^^^^^^^^\n",
      "  File \"c:\\Users\\plmar\\anaconda3\\Lib\\site-packages\\dash\\dash.py\", line 1310, in dispatch\n",
      "    ctx.run(\n",
      "  File \"c:\\Users\\plmar\\anaconda3\\Lib\\site-packages\\dash\\_callback.py\", line 442, in add_context\n",
      "    output_value = func(*func_args, **func_kwargs)  # %% callback invoked %%\n",
      "                   ^^^^^^^^^^^^^^^^^^^^^^^^^^^^^^^\n",
      "  File \"C:\\Users\\plmar\\AppData\\Local\\Temp\\ipykernel_88144\\1684445943.py\", line 78, in update_result\n",
      "    ymin = df.loc[relOut['xaxis.range'][1]:relOut['xaxis.range'][0],'y'].min()\n",
      "                  ~~~~~~^^^^^^^^^^^^^^^\n",
      "KeyError: 'xaxis.range'\n",
      "[2024-07-12 00:22:08,850] ERROR in app: Exception on /_dash-update-component [POST]\n",
      "Traceback (most recent call last):\n",
      "  File \"c:\\Users\\plmar\\anaconda3\\Lib\\site-packages\\flask\\app.py\", line 2525, in wsgi_app\n",
      "    response = self.full_dispatch_request()\n",
      "               ^^^^^^^^^^^^^^^^^^^^^^^^^^^^\n",
      "  File \"c:\\Users\\plmar\\anaconda3\\Lib\\site-packages\\flask\\app.py\", line 1822, in full_dispatch_request\n",
      "    rv = self.handle_user_exception(e)\n",
      "         ^^^^^^^^^^^^^^^^^^^^^^^^^^^^^\n",
      "  File \"c:\\Users\\plmar\\anaconda3\\Lib\\site-packages\\flask\\app.py\", line 1820, in full_dispatch_request\n",
      "    rv = self.dispatch_request()\n",
      "         ^^^^^^^^^^^^^^^^^^^^^^^\n",
      "  File \"c:\\Users\\plmar\\anaconda3\\Lib\\site-packages\\flask\\app.py\", line 1796, in dispatch_request\n",
      "    return self.ensure_sync(self.view_functions[rule.endpoint])(**view_args)\n",
      "           ^^^^^^^^^^^^^^^^^^^^^^^^^^^^^^^^^^^^^^^^^^^^^^^^^^^^^^^^^^^^^^^^^\n",
      "  File \"c:\\Users\\plmar\\anaconda3\\Lib\\site-packages\\dash\\dash.py\", line 1310, in dispatch\n",
      "    ctx.run(\n",
      "  File \"c:\\Users\\plmar\\anaconda3\\Lib\\site-packages\\dash\\_callback.py\", line 442, in add_context\n",
      "    output_value = func(*func_args, **func_kwargs)  # %% callback invoked %%\n",
      "                   ^^^^^^^^^^^^^^^^^^^^^^^^^^^^^^^\n",
      "  File \"C:\\Users\\plmar\\AppData\\Local\\Temp\\ipykernel_88144\\1684445943.py\", line 78, in update_result\n",
      "    ymin = df.loc[relOut['xaxis.range'][1]:relOut['xaxis.range'][0],'y'].min()\n",
      "                  ~~~~~~^^^^^^^^^^^^^^^\n",
      "KeyError: 'xaxis.range'\n",
      "[2024-07-12 00:22:09,228] ERROR in app: Exception on /_dash-update-component [POST]\n",
      "Traceback (most recent call last):\n",
      "  File \"c:\\Users\\plmar\\anaconda3\\Lib\\site-packages\\flask\\app.py\", line 2525, in wsgi_app\n",
      "    response = self.full_dispatch_request()\n",
      "               ^^^^^^^^^^^^^^^^^^^^^^^^^^^^\n",
      "  File \"c:\\Users\\plmar\\anaconda3\\Lib\\site-packages\\flask\\app.py\", line 1822, in full_dispatch_request\n",
      "    rv = self.handle_user_exception(e)\n",
      "         ^^^^^^^^^^^^^^^^^^^^^^^^^^^^^\n",
      "  File \"c:\\Users\\plmar\\anaconda3\\Lib\\site-packages\\flask\\app.py\", line 1820, in full_dispatch_request\n",
      "    rv = self.dispatch_request()\n",
      "         ^^^^^^^^^^^^^^^^^^^^^^^\n",
      "  File \"c:\\Users\\plmar\\anaconda3\\Lib\\site-packages\\flask\\app.py\", line 1796, in dispatch_request\n",
      "    return self.ensure_sync(self.view_functions[rule.endpoint])(**view_args)\n",
      "           ^^^^^^^^^^^^^^^^^^^^^^^^^^^^^^^^^^^^^^^^^^^^^^^^^^^^^^^^^^^^^^^^^\n",
      "  File \"c:\\Users\\plmar\\anaconda3\\Lib\\site-packages\\dash\\dash.py\", line 1310, in dispatch\n",
      "    ctx.run(\n",
      "  File \"c:\\Users\\plmar\\anaconda3\\Lib\\site-packages\\dash\\_callback.py\", line 442, in add_context\n",
      "    output_value = func(*func_args, **func_kwargs)  # %% callback invoked %%\n",
      "                   ^^^^^^^^^^^^^^^^^^^^^^^^^^^^^^^\n",
      "  File \"C:\\Users\\plmar\\AppData\\Local\\Temp\\ipykernel_88144\\1684445943.py\", line 78, in update_result\n",
      "    ymin = df.loc[relOut['xaxis.range'][1]:relOut['xaxis.range'][0],'y'].min()\n",
      "                  ~~~~~~^^^^^^^^^^^^^^^\n",
      "KeyError: 'xaxis.range'\n",
      "[2024-07-12 00:22:09,565] ERROR in app: Exception on /_dash-update-component [POST]\n",
      "Traceback (most recent call last):\n",
      "  File \"c:\\Users\\plmar\\anaconda3\\Lib\\site-packages\\flask\\app.py\", line 2525, in wsgi_app\n",
      "    response = self.full_dispatch_request()\n",
      "               ^^^^^^^^^^^^^^^^^^^^^^^^^^^^\n",
      "  File \"c:\\Users\\plmar\\anaconda3\\Lib\\site-packages\\flask\\app.py\", line 1822, in full_dispatch_request\n",
      "    rv = self.handle_user_exception(e)\n",
      "         ^^^^^^^^^^^^^^^^^^^^^^^^^^^^^\n",
      "  File \"c:\\Users\\plmar\\anaconda3\\Lib\\site-packages\\flask\\app.py\", line 1820, in full_dispatch_request\n",
      "    rv = self.dispatch_request()\n",
      "         ^^^^^^^^^^^^^^^^^^^^^^^\n",
      "  File \"c:\\Users\\plmar\\anaconda3\\Lib\\site-packages\\flask\\app.py\", line 1796, in dispatch_request\n",
      "    return self.ensure_sync(self.view_functions[rule.endpoint])(**view_args)\n",
      "           ^^^^^^^^^^^^^^^^^^^^^^^^^^^^^^^^^^^^^^^^^^^^^^^^^^^^^^^^^^^^^^^^^\n",
      "  File \"c:\\Users\\plmar\\anaconda3\\Lib\\site-packages\\dash\\dash.py\", line 1310, in dispatch\n",
      "    ctx.run(\n",
      "  File \"c:\\Users\\plmar\\anaconda3\\Lib\\site-packages\\dash\\_callback.py\", line 442, in add_context\n",
      "    output_value = func(*func_args, **func_kwargs)  # %% callback invoked %%\n",
      "                   ^^^^^^^^^^^^^^^^^^^^^^^^^^^^^^^\n",
      "  File \"C:\\Users\\plmar\\AppData\\Local\\Temp\\ipykernel_88144\\1684445943.py\", line 78, in update_result\n",
      "    ymin = df.loc[relOut['xaxis.range'][1]:relOut['xaxis.range'][0],'y'].min()\n",
      "                  ~~~~~~^^^^^^^^^^^^^^^\n",
      "KeyError: 'xaxis.range'\n",
      "[2024-07-12 00:22:10,038] ERROR in app: Exception on /_dash-update-component [POST]\n",
      "Traceback (most recent call last):\n",
      "  File \"c:\\Users\\plmar\\anaconda3\\Lib\\site-packages\\flask\\app.py\", line 2525, in wsgi_app\n",
      "    response = self.full_dispatch_request()\n",
      "               ^^^^^^^^^^^^^^^^^^^^^^^^^^^^\n",
      "  File \"c:\\Users\\plmar\\anaconda3\\Lib\\site-packages\\flask\\app.py\", line 1822, in full_dispatch_request\n",
      "    rv = self.handle_user_exception(e)\n",
      "         ^^^^^^^^^^^^^^^^^^^^^^^^^^^^^\n",
      "  File \"c:\\Users\\plmar\\anaconda3\\Lib\\site-packages\\flask\\app.py\", line 1820, in full_dispatch_request\n",
      "    rv = self.dispatch_request()\n",
      "         ^^^^^^^^^^^^^^^^^^^^^^^\n",
      "  File \"c:\\Users\\plmar\\anaconda3\\Lib\\site-packages\\flask\\app.py\", line 1796, in dispatch_request\n",
      "    return self.ensure_sync(self.view_functions[rule.endpoint])(**view_args)\n",
      "           ^^^^^^^^^^^^^^^^^^^^^^^^^^^^^^^^^^^^^^^^^^^^^^^^^^^^^^^^^^^^^^^^^\n",
      "  File \"c:\\Users\\plmar\\anaconda3\\Lib\\site-packages\\dash\\dash.py\", line 1310, in dispatch\n",
      "    ctx.run(\n",
      "  File \"c:\\Users\\plmar\\anaconda3\\Lib\\site-packages\\dash\\_callback.py\", line 442, in add_context\n",
      "    output_value = func(*func_args, **func_kwargs)  # %% callback invoked %%\n",
      "                   ^^^^^^^^^^^^^^^^^^^^^^^^^^^^^^^\n",
      "  File \"C:\\Users\\plmar\\AppData\\Local\\Temp\\ipykernel_88144\\1684445943.py\", line 78, in update_result\n",
      "    ymin = df.loc[relOut['xaxis.range'][1]:relOut['xaxis.range'][0],'y'].min()\n",
      "                  ~~~~~~^^^^^^^^^^^^^^^\n",
      "KeyError: 'xaxis.range'\n",
      "[2024-07-12 00:22:13,049] ERROR in app: Exception on /_dash-update-component [POST]\n",
      "Traceback (most recent call last):\n",
      "  File \"c:\\Users\\plmar\\anaconda3\\Lib\\site-packages\\flask\\app.py\", line 2525, in wsgi_app\n",
      "    response = self.full_dispatch_request()\n",
      "               ^^^^^^^^^^^^^^^^^^^^^^^^^^^^\n",
      "  File \"c:\\Users\\plmar\\anaconda3\\Lib\\site-packages\\flask\\app.py\", line 1822, in full_dispatch_request\n",
      "    rv = self.handle_user_exception(e)\n",
      "         ^^^^^^^^^^^^^^^^^^^^^^^^^^^^^\n",
      "  File \"c:\\Users\\plmar\\anaconda3\\Lib\\site-packages\\flask\\app.py\", line 1820, in full_dispatch_request\n",
      "    rv = self.dispatch_request()\n",
      "         ^^^^^^^^^^^^^^^^^^^^^^^\n",
      "  File \"c:\\Users\\plmar\\anaconda3\\Lib\\site-packages\\flask\\app.py\", line 1796, in dispatch_request\n",
      "    return self.ensure_sync(self.view_functions[rule.endpoint])(**view_args)\n",
      "           ^^^^^^^^^^^^^^^^^^^^^^^^^^^^^^^^^^^^^^^^^^^^^^^^^^^^^^^^^^^^^^^^^\n",
      "  File \"c:\\Users\\plmar\\anaconda3\\Lib\\site-packages\\dash\\dash.py\", line 1310, in dispatch\n",
      "    ctx.run(\n",
      "  File \"c:\\Users\\plmar\\anaconda3\\Lib\\site-packages\\dash\\_callback.py\", line 442, in add_context\n",
      "    output_value = func(*func_args, **func_kwargs)  # %% callback invoked %%\n",
      "                   ^^^^^^^^^^^^^^^^^^^^^^^^^^^^^^^\n",
      "  File \"C:\\Users\\plmar\\AppData\\Local\\Temp\\ipykernel_88144\\1684445943.py\", line 78, in update_result\n",
      "    ymin = df.loc[relOut['xaxis.range'][1]:relOut['xaxis.range'][0],'y'].min()\n",
      "                  ~~~~~~^^^^^^^^^^^^^^^\n",
      "KeyError: 'xaxis.range'\n",
      "[2024-07-12 00:22:13,389] ERROR in app: Exception on /_dash-update-component [POST]\n",
      "Traceback (most recent call last):\n",
      "  File \"c:\\Users\\plmar\\anaconda3\\Lib\\site-packages\\flask\\app.py\", line 2525, in wsgi_app\n",
      "    response = self.full_dispatch_request()\n",
      "               ^^^^^^^^^^^^^^^^^^^^^^^^^^^^\n",
      "  File \"c:\\Users\\plmar\\anaconda3\\Lib\\site-packages\\flask\\app.py\", line 1822, in full_dispatch_request\n",
      "    rv = self.handle_user_exception(e)\n",
      "         ^^^^^^^^^^^^^^^^^^^^^^^^^^^^^\n",
      "  File \"c:\\Users\\plmar\\anaconda3\\Lib\\site-packages\\flask\\app.py\", line 1820, in full_dispatch_request\n",
      "    rv = self.dispatch_request()\n",
      "         ^^^^^^^^^^^^^^^^^^^^^^^\n",
      "  File \"c:\\Users\\plmar\\anaconda3\\Lib\\site-packages\\flask\\app.py\", line 1796, in dispatch_request\n",
      "    return self.ensure_sync(self.view_functions[rule.endpoint])(**view_args)\n",
      "           ^^^^^^^^^^^^^^^^^^^^^^^^^^^^^^^^^^^^^^^^^^^^^^^^^^^^^^^^^^^^^^^^^\n",
      "  File \"c:\\Users\\plmar\\anaconda3\\Lib\\site-packages\\dash\\dash.py\", line 1310, in dispatch\n",
      "    ctx.run(\n",
      "  File \"c:\\Users\\plmar\\anaconda3\\Lib\\site-packages\\dash\\_callback.py\", line 442, in add_context\n",
      "    output_value = func(*func_args, **func_kwargs)  # %% callback invoked %%\n",
      "                   ^^^^^^^^^^^^^^^^^^^^^^^^^^^^^^^\n",
      "  File \"C:\\Users\\plmar\\AppData\\Local\\Temp\\ipykernel_88144\\1684445943.py\", line 78, in update_result\n",
      "    ymin = df.loc[relOut['xaxis.range'][1]:relOut['xaxis.range'][0],'y'].min()\n",
      "                  ~~~~~~^^^^^^^^^^^^^^^\n",
      "KeyError: 'xaxis.range'\n",
      "[2024-07-12 00:22:13,842] ERROR in app: Exception on /_dash-update-component [POST]\n",
      "Traceback (most recent call last):\n",
      "  File \"c:\\Users\\plmar\\anaconda3\\Lib\\site-packages\\flask\\app.py\", line 2525, in wsgi_app\n",
      "    response = self.full_dispatch_request()\n",
      "               ^^^^^^^^^^^^^^^^^^^^^^^^^^^^\n",
      "  File \"c:\\Users\\plmar\\anaconda3\\Lib\\site-packages\\flask\\app.py\", line 1822, in full_dispatch_request\n",
      "    rv = self.handle_user_exception(e)\n",
      "         ^^^^^^^^^^^^^^^^^^^^^^^^^^^^^\n",
      "  File \"c:\\Users\\plmar\\anaconda3\\Lib\\site-packages\\flask\\app.py\", line 1820, in full_dispatch_request\n",
      "    rv = self.dispatch_request()\n",
      "         ^^^^^^^^^^^^^^^^^^^^^^^\n",
      "  File \"c:\\Users\\plmar\\anaconda3\\Lib\\site-packages\\flask\\app.py\", line 1796, in dispatch_request\n",
      "    return self.ensure_sync(self.view_functions[rule.endpoint])(**view_args)\n",
      "           ^^^^^^^^^^^^^^^^^^^^^^^^^^^^^^^^^^^^^^^^^^^^^^^^^^^^^^^^^^^^^^^^^\n",
      "  File \"c:\\Users\\plmar\\anaconda3\\Lib\\site-packages\\dash\\dash.py\", line 1310, in dispatch\n",
      "    ctx.run(\n",
      "  File \"c:\\Users\\plmar\\anaconda3\\Lib\\site-packages\\dash\\_callback.py\", line 442, in add_context\n",
      "    output_value = func(*func_args, **func_kwargs)  # %% callback invoked %%\n",
      "                   ^^^^^^^^^^^^^^^^^^^^^^^^^^^^^^^\n",
      "  File \"C:\\Users\\plmar\\AppData\\Local\\Temp\\ipykernel_88144\\1684445943.py\", line 78, in update_result\n",
      "    ymin = df.loc[relOut['xaxis.range'][1]:relOut['xaxis.range'][0],'y'].min()\n",
      "                  ~~~~~~^^^^^^^^^^^^^^^\n",
      "KeyError: 'xaxis.range'\n",
      "[2024-07-12 00:22:14,311] ERROR in app: Exception on /_dash-update-component [POST]\n",
      "Traceback (most recent call last):\n",
      "  File \"c:\\Users\\plmar\\anaconda3\\Lib\\site-packages\\flask\\app.py\", line 2525, in wsgi_app\n",
      "    response = self.full_dispatch_request()\n",
      "               ^^^^^^^^^^^^^^^^^^^^^^^^^^^^\n",
      "  File \"c:\\Users\\plmar\\anaconda3\\Lib\\site-packages\\flask\\app.py\", line 1822, in full_dispatch_request\n",
      "    rv = self.handle_user_exception(e)\n",
      "         ^^^^^^^^^^^^^^^^^^^^^^^^^^^^^\n",
      "  File \"c:\\Users\\plmar\\anaconda3\\Lib\\site-packages\\flask\\app.py\", line 1820, in full_dispatch_request\n",
      "    rv = self.dispatch_request()\n",
      "         ^^^^^^^^^^^^^^^^^^^^^^^\n",
      "  File \"c:\\Users\\plmar\\anaconda3\\Lib\\site-packages\\flask\\app.py\", line 1796, in dispatch_request\n",
      "    return self.ensure_sync(self.view_functions[rule.endpoint])(**view_args)\n",
      "           ^^^^^^^^^^^^^^^^^^^^^^^^^^^^^^^^^^^^^^^^^^^^^^^^^^^^^^^^^^^^^^^^^\n",
      "  File \"c:\\Users\\plmar\\anaconda3\\Lib\\site-packages\\dash\\dash.py\", line 1310, in dispatch\n",
      "    ctx.run(\n",
      "  File \"c:\\Users\\plmar\\anaconda3\\Lib\\site-packages\\dash\\_callback.py\", line 442, in add_context\n",
      "    output_value = func(*func_args, **func_kwargs)  # %% callback invoked %%\n",
      "                   ^^^^^^^^^^^^^^^^^^^^^^^^^^^^^^^\n",
      "  File \"C:\\Users\\plmar\\AppData\\Local\\Temp\\ipykernel_88144\\1684445943.py\", line 78, in update_result\n",
      "    ymin = df.loc[relOut['xaxis.range'][1]:relOut['xaxis.range'][0],'y'].min()\n",
      "                  ~~~~~~^^^^^^^^^^^^^^^\n",
      "KeyError: 'xaxis.range'\n",
      "[2024-07-12 00:22:15,066] ERROR in app: Exception on /_dash-update-component [POST]\n",
      "Traceback (most recent call last):\n",
      "  File \"c:\\Users\\plmar\\anaconda3\\Lib\\site-packages\\flask\\app.py\", line 2525, in wsgi_app\n",
      "    response = self.full_dispatch_request()\n",
      "               ^^^^^^^^^^^^^^^^^^^^^^^^^^^^\n",
      "  File \"c:\\Users\\plmar\\anaconda3\\Lib\\site-packages\\flask\\app.py\", line 1822, in full_dispatch_request\n",
      "    rv = self.handle_user_exception(e)\n",
      "         ^^^^^^^^^^^^^^^^^^^^^^^^^^^^^\n",
      "  File \"c:\\Users\\plmar\\anaconda3\\Lib\\site-packages\\flask\\app.py\", line 1820, in full_dispatch_request\n",
      "    rv = self.dispatch_request()\n",
      "         ^^^^^^^^^^^^^^^^^^^^^^^\n",
      "  File \"c:\\Users\\plmar\\anaconda3\\Lib\\site-packages\\flask\\app.py\", line 1796, in dispatch_request\n",
      "    return self.ensure_sync(self.view_functions[rule.endpoint])(**view_args)\n",
      "           ^^^^^^^^^^^^^^^^^^^^^^^^^^^^^^^^^^^^^^^^^^^^^^^^^^^^^^^^^^^^^^^^^\n",
      "  File \"c:\\Users\\plmar\\anaconda3\\Lib\\site-packages\\dash\\dash.py\", line 1310, in dispatch\n",
      "    ctx.run(\n",
      "  File \"c:\\Users\\plmar\\anaconda3\\Lib\\site-packages\\dash\\_callback.py\", line 442, in add_context\n",
      "    output_value = func(*func_args, **func_kwargs)  # %% callback invoked %%\n",
      "                   ^^^^^^^^^^^^^^^^^^^^^^^^^^^^^^^\n",
      "  File \"C:\\Users\\plmar\\AppData\\Local\\Temp\\ipykernel_88144\\1684445943.py\", line 78, in update_result\n",
      "    ymin = df.loc[relOut['xaxis.range'][1]:relOut['xaxis.range'][0],'y'].min()\n",
      "                  ~~~~~~^^^^^^^^^^^^^^^\n",
      "KeyError: 'xaxis.range'\n",
      "[2024-07-12 00:22:25,593] ERROR in app: Exception on /_dash-update-component [POST]\n",
      "Traceback (most recent call last):\n",
      "  File \"c:\\Users\\plmar\\anaconda3\\Lib\\site-packages\\flask\\app.py\", line 2525, in wsgi_app\n",
      "    response = self.full_dispatch_request()\n",
      "               ^^^^^^^^^^^^^^^^^^^^^^^^^^^^\n",
      "  File \"c:\\Users\\plmar\\anaconda3\\Lib\\site-packages\\flask\\app.py\", line 1822, in full_dispatch_request\n",
      "    rv = self.handle_user_exception(e)\n",
      "         ^^^^^^^^^^^^^^^^^^^^^^^^^^^^^\n",
      "  File \"c:\\Users\\plmar\\anaconda3\\Lib\\site-packages\\flask\\app.py\", line 1820, in full_dispatch_request\n",
      "    rv = self.dispatch_request()\n",
      "         ^^^^^^^^^^^^^^^^^^^^^^^\n",
      "  File \"c:\\Users\\plmar\\anaconda3\\Lib\\site-packages\\flask\\app.py\", line 1796, in dispatch_request\n",
      "    return self.ensure_sync(self.view_functions[rule.endpoint])(**view_args)\n",
      "           ^^^^^^^^^^^^^^^^^^^^^^^^^^^^^^^^^^^^^^^^^^^^^^^^^^^^^^^^^^^^^^^^^\n",
      "  File \"c:\\Users\\plmar\\anaconda3\\Lib\\site-packages\\dash\\dash.py\", line 1310, in dispatch\n",
      "    ctx.run(\n",
      "  File \"c:\\Users\\plmar\\anaconda3\\Lib\\site-packages\\dash\\_callback.py\", line 442, in add_context\n",
      "    output_value = func(*func_args, **func_kwargs)  # %% callback invoked %%\n",
      "                   ^^^^^^^^^^^^^^^^^^^^^^^^^^^^^^^\n",
      "  File \"C:\\Users\\plmar\\AppData\\Local\\Temp\\ipykernel_88144\\1684445943.py\", line 78, in update_result\n",
      "    ymin = df.loc[relOut['xaxis.range'][1]:relOut['xaxis.range'][0],'y'].min()\n",
      "                  ~~~~~~^^^^^^^^^^^^^^^\n",
      "KeyError: 'xaxis.range'\n",
      "[2024-07-12 00:22:25,947] ERROR in app: Exception on /_dash-update-component [POST]\n",
      "Traceback (most recent call last):\n",
      "  File \"c:\\Users\\plmar\\anaconda3\\Lib\\site-packages\\flask\\app.py\", line 2525, in wsgi_app\n",
      "    response = self.full_dispatch_request()\n",
      "               ^^^^^^^^^^^^^^^^^^^^^^^^^^^^\n",
      "  File \"c:\\Users\\plmar\\anaconda3\\Lib\\site-packages\\flask\\app.py\", line 1822, in full_dispatch_request\n",
      "    rv = self.handle_user_exception(e)\n",
      "         ^^^^^^^^^^^^^^^^^^^^^^^^^^^^^\n",
      "  File \"c:\\Users\\plmar\\anaconda3\\Lib\\site-packages\\flask\\app.py\", line 1820, in full_dispatch_request\n",
      "    rv = self.dispatch_request()\n",
      "         ^^^^^^^^^^^^^^^^^^^^^^^\n",
      "  File \"c:\\Users\\plmar\\anaconda3\\Lib\\site-packages\\flask\\app.py\", line 1796, in dispatch_request\n",
      "    return self.ensure_sync(self.view_functions[rule.endpoint])(**view_args)\n",
      "           ^^^^^^^^^^^^^^^^^^^^^^^^^^^^^^^^^^^^^^^^^^^^^^^^^^^^^^^^^^^^^^^^^\n",
      "  File \"c:\\Users\\plmar\\anaconda3\\Lib\\site-packages\\dash\\dash.py\", line 1310, in dispatch\n",
      "    ctx.run(\n",
      "  File \"c:\\Users\\plmar\\anaconda3\\Lib\\site-packages\\dash\\_callback.py\", line 442, in add_context\n",
      "    output_value = func(*func_args, **func_kwargs)  # %% callback invoked %%\n",
      "                   ^^^^^^^^^^^^^^^^^^^^^^^^^^^^^^^\n",
      "  File \"C:\\Users\\plmar\\AppData\\Local\\Temp\\ipykernel_88144\\1684445943.py\", line 78, in update_result\n",
      "    ymin = df.loc[relOut['xaxis.range'][1]:relOut['xaxis.range'][0],'y'].min()\n",
      "                  ~~~~~~^^^^^^^^^^^^^^^\n",
      "KeyError: 'xaxis.range'\n",
      "[2024-07-12 00:22:26,186] ERROR in app: Exception on /_dash-update-component [POST]\n",
      "Traceback (most recent call last):\n",
      "  File \"c:\\Users\\plmar\\anaconda3\\Lib\\site-packages\\flask\\app.py\", line 2525, in wsgi_app\n",
      "    response = self.full_dispatch_request()\n",
      "               ^^^^^^^^^^^^^^^^^^^^^^^^^^^^\n",
      "  File \"c:\\Users\\plmar\\anaconda3\\Lib\\site-packages\\flask\\app.py\", line 1822, in full_dispatch_request\n",
      "    rv = self.handle_user_exception(e)\n",
      "         ^^^^^^^^^^^^^^^^^^^^^^^^^^^^^\n",
      "  File \"c:\\Users\\plmar\\anaconda3\\Lib\\site-packages\\flask\\app.py\", line 1820, in full_dispatch_request\n",
      "    rv = self.dispatch_request()\n",
      "         ^^^^^^^^^^^^^^^^^^^^^^^\n",
      "  File \"c:\\Users\\plmar\\anaconda3\\Lib\\site-packages\\flask\\app.py\", line 1796, in dispatch_request\n",
      "    return self.ensure_sync(self.view_functions[rule.endpoint])(**view_args)\n",
      "           ^^^^^^^^^^^^^^^^^^^^^^^^^^^^^^^^^^^^^^^^^^^^^^^^^^^^^^^^^^^^^^^^^\n",
      "  File \"c:\\Users\\plmar\\anaconda3\\Lib\\site-packages\\dash\\dash.py\", line 1310, in dispatch\n",
      "    ctx.run(\n",
      "  File \"c:\\Users\\plmar\\anaconda3\\Lib\\site-packages\\dash\\_callback.py\", line 442, in add_context\n",
      "    output_value = func(*func_args, **func_kwargs)  # %% callback invoked %%\n",
      "                   ^^^^^^^^^^^^^^^^^^^^^^^^^^^^^^^\n",
      "  File \"C:\\Users\\plmar\\AppData\\Local\\Temp\\ipykernel_88144\\1684445943.py\", line 78, in update_result\n",
      "    ymin = df.loc[relOut['xaxis.range'][1]:relOut['xaxis.range'][0],'y'].min()\n",
      "                  ~~~~~~^^^^^^^^^^^^^^^\n",
      "KeyError: 'xaxis.range'\n",
      "[2024-07-12 00:22:26,433] ERROR in app: Exception on /_dash-update-component [POST]\n",
      "Traceback (most recent call last):\n",
      "  File \"c:\\Users\\plmar\\anaconda3\\Lib\\site-packages\\flask\\app.py\", line 2525, in wsgi_app\n",
      "    response = self.full_dispatch_request()\n",
      "               ^^^^^^^^^^^^^^^^^^^^^^^^^^^^\n",
      "  File \"c:\\Users\\plmar\\anaconda3\\Lib\\site-packages\\flask\\app.py\", line 1822, in full_dispatch_request\n",
      "    rv = self.handle_user_exception(e)\n",
      "         ^^^^^^^^^^^^^^^^^^^^^^^^^^^^^\n",
      "  File \"c:\\Users\\plmar\\anaconda3\\Lib\\site-packages\\flask\\app.py\", line 1820, in full_dispatch_request\n",
      "    rv = self.dispatch_request()\n",
      "         ^^^^^^^^^^^^^^^^^^^^^^^\n",
      "  File \"c:\\Users\\plmar\\anaconda3\\Lib\\site-packages\\flask\\app.py\", line 1796, in dispatch_request\n",
      "    return self.ensure_sync(self.view_functions[rule.endpoint])(**view_args)\n",
      "           ^^^^^^^^^^^^^^^^^^^^^^^^^^^^^^^^^^^^^^^^^^^^^^^^^^^^^^^^^^^^^^^^^\n",
      "  File \"c:\\Users\\plmar\\anaconda3\\Lib\\site-packages\\dash\\dash.py\", line 1310, in dispatch\n",
      "    ctx.run(\n",
      "  File \"c:\\Users\\plmar\\anaconda3\\Lib\\site-packages\\dash\\_callback.py\", line 442, in add_context\n",
      "    output_value = func(*func_args, **func_kwargs)  # %% callback invoked %%\n",
      "                   ^^^^^^^^^^^^^^^^^^^^^^^^^^^^^^^\n",
      "  File \"C:\\Users\\plmar\\AppData\\Local\\Temp\\ipykernel_88144\\1684445943.py\", line 78, in update_result\n",
      "    ymin = df.loc[relOut['xaxis.range'][1]:relOut['xaxis.range'][0],'y'].min()\n",
      "                  ~~~~~~^^^^^^^^^^^^^^^\n",
      "KeyError: 'xaxis.range'\n",
      "[2024-07-12 00:22:30,437] ERROR in app: Exception on /_dash-update-component [POST]\n",
      "Traceback (most recent call last):\n",
      "  File \"c:\\Users\\plmar\\anaconda3\\Lib\\site-packages\\flask\\app.py\", line 2525, in wsgi_app\n",
      "    response = self.full_dispatch_request()\n",
      "               ^^^^^^^^^^^^^^^^^^^^^^^^^^^^\n",
      "  File \"c:\\Users\\plmar\\anaconda3\\Lib\\site-packages\\flask\\app.py\", line 1822, in full_dispatch_request\n",
      "    rv = self.handle_user_exception(e)\n",
      "         ^^^^^^^^^^^^^^^^^^^^^^^^^^^^^\n",
      "  File \"c:\\Users\\plmar\\anaconda3\\Lib\\site-packages\\flask\\app.py\", line 1820, in full_dispatch_request\n",
      "    rv = self.dispatch_request()\n",
      "         ^^^^^^^^^^^^^^^^^^^^^^^\n",
      "  File \"c:\\Users\\plmar\\anaconda3\\Lib\\site-packages\\flask\\app.py\", line 1796, in dispatch_request\n",
      "    return self.ensure_sync(self.view_functions[rule.endpoint])(**view_args)\n",
      "           ^^^^^^^^^^^^^^^^^^^^^^^^^^^^^^^^^^^^^^^^^^^^^^^^^^^^^^^^^^^^^^^^^\n",
      "  File \"c:\\Users\\plmar\\anaconda3\\Lib\\site-packages\\dash\\dash.py\", line 1310, in dispatch\n",
      "    ctx.run(\n",
      "  File \"c:\\Users\\plmar\\anaconda3\\Lib\\site-packages\\dash\\_callback.py\", line 442, in add_context\n",
      "    output_value = func(*func_args, **func_kwargs)  # %% callback invoked %%\n",
      "                   ^^^^^^^^^^^^^^^^^^^^^^^^^^^^^^^\n",
      "  File \"C:\\Users\\plmar\\AppData\\Local\\Temp\\ipykernel_88144\\1684445943.py\", line 78, in update_result\n",
      "    ymin = df.loc[relOut['xaxis.range'][1]:relOut['xaxis.range'][0],'y'].min()\n",
      "                  ~~~~~~^^^^^^^^^^^^^^^\n",
      "KeyError: 'xaxis.range'\n",
      "[2024-07-12 00:22:30,751] ERROR in app: Exception on /_dash-update-component [POST]\n",
      "Traceback (most recent call last):\n",
      "  File \"c:\\Users\\plmar\\anaconda3\\Lib\\site-packages\\flask\\app.py\", line 2525, in wsgi_app\n",
      "    response = self.full_dispatch_request()\n",
      "               ^^^^^^^^^^^^^^^^^^^^^^^^^^^^\n",
      "  File \"c:\\Users\\plmar\\anaconda3\\Lib\\site-packages\\flask\\app.py\", line 1822, in full_dispatch_request\n",
      "    rv = self.handle_user_exception(e)\n",
      "         ^^^^^^^^^^^^^^^^^^^^^^^^^^^^^\n",
      "  File \"c:\\Users\\plmar\\anaconda3\\Lib\\site-packages\\flask\\app.py\", line 1820, in full_dispatch_request\n",
      "    rv = self.dispatch_request()\n",
      "         ^^^^^^^^^^^^^^^^^^^^^^^\n",
      "  File \"c:\\Users\\plmar\\anaconda3\\Lib\\site-packages\\flask\\app.py\", line 1796, in dispatch_request\n",
      "    return self.ensure_sync(self.view_functions[rule.endpoint])(**view_args)\n",
      "           ^^^^^^^^^^^^^^^^^^^^^^^^^^^^^^^^^^^^^^^^^^^^^^^^^^^^^^^^^^^^^^^^^\n",
      "  File \"c:\\Users\\plmar\\anaconda3\\Lib\\site-packages\\dash\\dash.py\", line 1310, in dispatch\n",
      "    ctx.run(\n",
      "  File \"c:\\Users\\plmar\\anaconda3\\Lib\\site-packages\\dash\\_callback.py\", line 442, in add_context\n",
      "    output_value = func(*func_args, **func_kwargs)  # %% callback invoked %%\n",
      "                   ^^^^^^^^^^^^^^^^^^^^^^^^^^^^^^^\n",
      "  File \"C:\\Users\\plmar\\AppData\\Local\\Temp\\ipykernel_88144\\1684445943.py\", line 78, in update_result\n",
      "    ymin = df.loc[relOut['xaxis.range'][1]:relOut['xaxis.range'][0],'y'].min()\n",
      "                  ~~~~~~^^^^^^^^^^^^^^^\n",
      "KeyError: 'xaxis.range'\n",
      "[2024-07-12 00:22:31,003] ERROR in app: Exception on /_dash-update-component [POST]\n",
      "Traceback (most recent call last):\n",
      "  File \"c:\\Users\\plmar\\anaconda3\\Lib\\site-packages\\flask\\app.py\", line 2525, in wsgi_app\n",
      "    response = self.full_dispatch_request()\n",
      "               ^^^^^^^^^^^^^^^^^^^^^^^^^^^^\n",
      "  File \"c:\\Users\\plmar\\anaconda3\\Lib\\site-packages\\flask\\app.py\", line 1822, in full_dispatch_request\n",
      "    rv = self.handle_user_exception(e)\n",
      "         ^^^^^^^^^^^^^^^^^^^^^^^^^^^^^\n",
      "  File \"c:\\Users\\plmar\\anaconda3\\Lib\\site-packages\\flask\\app.py\", line 1820, in full_dispatch_request\n",
      "    rv = self.dispatch_request()\n",
      "         ^^^^^^^^^^^^^^^^^^^^^^^\n",
      "  File \"c:\\Users\\plmar\\anaconda3\\Lib\\site-packages\\flask\\app.py\", line 1796, in dispatch_request\n",
      "    return self.ensure_sync(self.view_functions[rule.endpoint])(**view_args)\n",
      "           ^^^^^^^^^^^^^^^^^^^^^^^^^^^^^^^^^^^^^^^^^^^^^^^^^^^^^^^^^^^^^^^^^\n",
      "  File \"c:\\Users\\plmar\\anaconda3\\Lib\\site-packages\\dash\\dash.py\", line 1310, in dispatch\n",
      "    ctx.run(\n",
      "  File \"c:\\Users\\plmar\\anaconda3\\Lib\\site-packages\\dash\\_callback.py\", line 442, in add_context\n",
      "    output_value = func(*func_args, **func_kwargs)  # %% callback invoked %%\n",
      "                   ^^^^^^^^^^^^^^^^^^^^^^^^^^^^^^^\n",
      "  File \"C:\\Users\\plmar\\AppData\\Local\\Temp\\ipykernel_88144\\1684445943.py\", line 78, in update_result\n",
      "    ymin = df.loc[relOut['xaxis.range'][1]:relOut['xaxis.range'][0],'y'].min()\n",
      "                  ~~~~~~^^^^^^^^^^^^^^^\n",
      "KeyError: 'xaxis.range'\n",
      "[2024-07-12 00:22:31,326] ERROR in app: Exception on /_dash-update-component [POST]\n",
      "Traceback (most recent call last):\n",
      "  File \"c:\\Users\\plmar\\anaconda3\\Lib\\site-packages\\flask\\app.py\", line 2525, in wsgi_app\n",
      "    response = self.full_dispatch_request()\n",
      "               ^^^^^^^^^^^^^^^^^^^^^^^^^^^^\n",
      "  File \"c:\\Users\\plmar\\anaconda3\\Lib\\site-packages\\flask\\app.py\", line 1822, in full_dispatch_request\n",
      "    rv = self.handle_user_exception(e)\n",
      "         ^^^^^^^^^^^^^^^^^^^^^^^^^^^^^\n",
      "  File \"c:\\Users\\plmar\\anaconda3\\Lib\\site-packages\\flask\\app.py\", line 1820, in full_dispatch_request\n",
      "    rv = self.dispatch_request()\n",
      "         ^^^^^^^^^^^^^^^^^^^^^^^\n",
      "  File \"c:\\Users\\plmar\\anaconda3\\Lib\\site-packages\\flask\\app.py\", line 1796, in dispatch_request\n",
      "    return self.ensure_sync(self.view_functions[rule.endpoint])(**view_args)\n",
      "           ^^^^^^^^^^^^^^^^^^^^^^^^^^^^^^^^^^^^^^^^^^^^^^^^^^^^^^^^^^^^^^^^^\n",
      "  File \"c:\\Users\\plmar\\anaconda3\\Lib\\site-packages\\dash\\dash.py\", line 1310, in dispatch\n",
      "    ctx.run(\n",
      "  File \"c:\\Users\\plmar\\anaconda3\\Lib\\site-packages\\dash\\_callback.py\", line 442, in add_context\n",
      "    output_value = func(*func_args, **func_kwargs)  # %% callback invoked %%\n",
      "                   ^^^^^^^^^^^^^^^^^^^^^^^^^^^^^^^\n",
      "  File \"C:\\Users\\plmar\\AppData\\Local\\Temp\\ipykernel_88144\\1684445943.py\", line 78, in update_result\n",
      "    ymin = df.loc[relOut['xaxis.range'][1]:relOut['xaxis.range'][0],'y'].min()\n",
      "                  ~~~~~~^^^^^^^^^^^^^^^\n",
      "KeyError: 'xaxis.range'\n",
      "[2024-07-12 00:22:31,825] ERROR in app: Exception on /_dash-update-component [POST]\n",
      "Traceback (most recent call last):\n",
      "  File \"c:\\Users\\plmar\\anaconda3\\Lib\\site-packages\\flask\\app.py\", line 2525, in wsgi_app\n",
      "    response = self.full_dispatch_request()\n",
      "               ^^^^^^^^^^^^^^^^^^^^^^^^^^^^\n",
      "  File \"c:\\Users\\plmar\\anaconda3\\Lib\\site-packages\\flask\\app.py\", line 1822, in full_dispatch_request\n",
      "    rv = self.handle_user_exception(e)\n",
      "         ^^^^^^^^^^^^^^^^^^^^^^^^^^^^^\n",
      "  File \"c:\\Users\\plmar\\anaconda3\\Lib\\site-packages\\flask\\app.py\", line 1820, in full_dispatch_request\n",
      "    rv = self.dispatch_request()\n",
      "         ^^^^^^^^^^^^^^^^^^^^^^^\n",
      "  File \"c:\\Users\\plmar\\anaconda3\\Lib\\site-packages\\flask\\app.py\", line 1796, in dispatch_request\n",
      "    return self.ensure_sync(self.view_functions[rule.endpoint])(**view_args)\n",
      "           ^^^^^^^^^^^^^^^^^^^^^^^^^^^^^^^^^^^^^^^^^^^^^^^^^^^^^^^^^^^^^^^^^\n",
      "  File \"c:\\Users\\plmar\\anaconda3\\Lib\\site-packages\\dash\\dash.py\", line 1310, in dispatch\n",
      "    ctx.run(\n",
      "  File \"c:\\Users\\plmar\\anaconda3\\Lib\\site-packages\\dash\\_callback.py\", line 442, in add_context\n",
      "    output_value = func(*func_args, **func_kwargs)  # %% callback invoked %%\n",
      "                   ^^^^^^^^^^^^^^^^^^^^^^^^^^^^^^^\n",
      "  File \"C:\\Users\\plmar\\AppData\\Local\\Temp\\ipykernel_88144\\1684445943.py\", line 78, in update_result\n",
      "    ymin = df.loc[relOut['xaxis.range'][1]:relOut['xaxis.range'][0],'y'].min()\n",
      "                  ~~~~~~^^^^^^^^^^^^^^^\n",
      "KeyError: 'xaxis.range'\n",
      "[2024-07-12 00:22:32,109] ERROR in app: Exception on /_dash-update-component [POST]\n",
      "Traceback (most recent call last):\n",
      "  File \"c:\\Users\\plmar\\anaconda3\\Lib\\site-packages\\flask\\app.py\", line 2525, in wsgi_app\n",
      "    response = self.full_dispatch_request()\n",
      "               ^^^^^^^^^^^^^^^^^^^^^^^^^^^^\n",
      "  File \"c:\\Users\\plmar\\anaconda3\\Lib\\site-packages\\flask\\app.py\", line 1822, in full_dispatch_request\n",
      "    rv = self.handle_user_exception(e)\n",
      "         ^^^^^^^^^^^^^^^^^^^^^^^^^^^^^\n",
      "  File \"c:\\Users\\plmar\\anaconda3\\Lib\\site-packages\\flask\\app.py\", line 1820, in full_dispatch_request\n",
      "    rv = self.dispatch_request()\n",
      "         ^^^^^^^^^^^^^^^^^^^^^^^\n",
      "  File \"c:\\Users\\plmar\\anaconda3\\Lib\\site-packages\\flask\\app.py\", line 1796, in dispatch_request\n",
      "    return self.ensure_sync(self.view_functions[rule.endpoint])(**view_args)\n",
      "           ^^^^^^^^^^^^^^^^^^^^^^^^^^^^^^^^^^^^^^^^^^^^^^^^^^^^^^^^^^^^^^^^^\n",
      "  File \"c:\\Users\\plmar\\anaconda3\\Lib\\site-packages\\dash\\dash.py\", line 1310, in dispatch\n",
      "    ctx.run(\n",
      "  File \"c:\\Users\\plmar\\anaconda3\\Lib\\site-packages\\dash\\_callback.py\", line 442, in add_context\n",
      "    output_value = func(*func_args, **func_kwargs)  # %% callback invoked %%\n",
      "                   ^^^^^^^^^^^^^^^^^^^^^^^^^^^^^^^\n",
      "  File \"C:\\Users\\plmar\\AppData\\Local\\Temp\\ipykernel_88144\\1684445943.py\", line 78, in update_result\n",
      "    ymin = df.loc[relOut['xaxis.range'][1]:relOut['xaxis.range'][0],'y'].min()\n",
      "                  ~~~~~~^^^^^^^^^^^^^^^\n",
      "KeyError: 'xaxis.range'\n",
      "[2024-07-12 00:22:32,405] ERROR in app: Exception on /_dash-update-component [POST]\n",
      "Traceback (most recent call last):\n",
      "  File \"c:\\Users\\plmar\\anaconda3\\Lib\\site-packages\\flask\\app.py\", line 2525, in wsgi_app\n",
      "    response = self.full_dispatch_request()\n",
      "               ^^^^^^^^^^^^^^^^^^^^^^^^^^^^\n",
      "  File \"c:\\Users\\plmar\\anaconda3\\Lib\\site-packages\\flask\\app.py\", line 1822, in full_dispatch_request\n",
      "    rv = self.handle_user_exception(e)\n",
      "         ^^^^^^^^^^^^^^^^^^^^^^^^^^^^^\n",
      "  File \"c:\\Users\\plmar\\anaconda3\\Lib\\site-packages\\flask\\app.py\", line 1820, in full_dispatch_request\n",
      "    rv = self.dispatch_request()\n",
      "         ^^^^^^^^^^^^^^^^^^^^^^^\n",
      "  File \"c:\\Users\\plmar\\anaconda3\\Lib\\site-packages\\flask\\app.py\", line 1796, in dispatch_request\n",
      "    return self.ensure_sync(self.view_functions[rule.endpoint])(**view_args)\n",
      "           ^^^^^^^^^^^^^^^^^^^^^^^^^^^^^^^^^^^^^^^^^^^^^^^^^^^^^^^^^^^^^^^^^\n",
      "  File \"c:\\Users\\plmar\\anaconda3\\Lib\\site-packages\\dash\\dash.py\", line 1310, in dispatch\n",
      "    ctx.run(\n",
      "  File \"c:\\Users\\plmar\\anaconda3\\Lib\\site-packages\\dash\\_callback.py\", line 442, in add_context\n",
      "    output_value = func(*func_args, **func_kwargs)  # %% callback invoked %%\n",
      "                   ^^^^^^^^^^^^^^^^^^^^^^^^^^^^^^^\n",
      "  File \"C:\\Users\\plmar\\AppData\\Local\\Temp\\ipykernel_88144\\1684445943.py\", line 78, in update_result\n",
      "    ymin = df.loc[relOut['xaxis.range'][1]:relOut['xaxis.range'][0],'y'].min()\n",
      "                  ~~~~~~^^^^^^^^^^^^^^^\n",
      "KeyError: 'xaxis.range'\n",
      "[2024-07-12 00:22:32,748] ERROR in app: Exception on /_dash-update-component [POST]\n",
      "Traceback (most recent call last):\n",
      "  File \"c:\\Users\\plmar\\anaconda3\\Lib\\site-packages\\flask\\app.py\", line 2525, in wsgi_app\n",
      "    response = self.full_dispatch_request()\n",
      "               ^^^^^^^^^^^^^^^^^^^^^^^^^^^^\n",
      "  File \"c:\\Users\\plmar\\anaconda3\\Lib\\site-packages\\flask\\app.py\", line 1822, in full_dispatch_request\n",
      "    rv = self.handle_user_exception(e)\n",
      "         ^^^^^^^^^^^^^^^^^^^^^^^^^^^^^\n",
      "  File \"c:\\Users\\plmar\\anaconda3\\Lib\\site-packages\\flask\\app.py\", line 1820, in full_dispatch_request\n",
      "    rv = self.dispatch_request()\n",
      "         ^^^^^^^^^^^^^^^^^^^^^^^\n",
      "  File \"c:\\Users\\plmar\\anaconda3\\Lib\\site-packages\\flask\\app.py\", line 1796, in dispatch_request\n",
      "    return self.ensure_sync(self.view_functions[rule.endpoint])(**view_args)\n",
      "           ^^^^^^^^^^^^^^^^^^^^^^^^^^^^^^^^^^^^^^^^^^^^^^^^^^^^^^^^^^^^^^^^^\n",
      "  File \"c:\\Users\\plmar\\anaconda3\\Lib\\site-packages\\dash\\dash.py\", line 1310, in dispatch\n",
      "    ctx.run(\n",
      "  File \"c:\\Users\\plmar\\anaconda3\\Lib\\site-packages\\dash\\_callback.py\", line 442, in add_context\n",
      "    output_value = func(*func_args, **func_kwargs)  # %% callback invoked %%\n",
      "                   ^^^^^^^^^^^^^^^^^^^^^^^^^^^^^^^\n",
      "  File \"C:\\Users\\plmar\\AppData\\Local\\Temp\\ipykernel_88144\\1684445943.py\", line 78, in update_result\n",
      "    ymin = df.loc[relOut['xaxis.range'][1]:relOut['xaxis.range'][0],'y'].min()\n",
      "                  ~~~~~~^^^^^^^^^^^^^^^\n",
      "KeyError: 'xaxis.range'\n"
     ]
    }
   ],
   "source": [
    "import dash\n",
    "from dash.dependencies import Output, Input, State\n",
    "import dash_core_components as dcc\n",
    "import dash_html_components as html\n",
    "import plotly.graph_objs as go\n",
    "import numpy as np\n",
    "import pandas as pd\n",
    "import datetime\n",
    "\n",
    "#some random values\n",
    "a = datetime.datetime.today()\n",
    "numdays = 100\n",
    "dateList = []\n",
    "for x in range (0, numdays):\n",
    "    dateList.append(a - datetime.timedelta(days = x))\n",
    "xy = [dateList,np.random.rand(100)]\n",
    "\n",
    "df = pd.DataFrame(data=xy[1],columns=[\"y\"],index=xy[0])\n",
    "\n",
    "app = dash.Dash()\n",
    "\n",
    "app.title = 'Random'\n",
    "\n",
    "dataS = [dict(\n",
    "    x = df.index,\n",
    "    y = df['y'],\n",
    "    name = 'OL meter',\n",
    "    mode = 'lines'\n",
    ")]\n",
    "\n",
    "def uptLayout(yaxRang):\n",
    "    return \n",
    "\n",
    "\n",
    "layoutS = go.Layout(\n",
    "    title=\"OL Meter\",\n",
    "    xaxis=dict(\n",
    "        rangeslider_visible=True,\n",
    "        rangeselector=dict(\n",
    "            buttons=list([\n",
    "                dict(count=0, label=\"1m\", step=\"month\", stepmode=\"backward\"),\n",
    "                dict(count=6, label=\"6m\", step=\"month\", stepmode=\"backward\"),\n",
    "                dict(count=1, label=\"YTD\", step=\"year\", stepmode=\"todate\"),\n",
    "                dict(count=1, label=\"1y\", step=\"year\", stepmode=\"backward\"),\n",
    "                dict(count=5, label=\"5y\", step=\"year\", stepmode=\"backward\"),\n",
    "                dict(step=\"all\")\n",
    "            ])\n",
    "        )\n",
    "    ),\n",
    "    yaxis=dict(range=[0,2])\n",
    ")\n",
    "\n",
    "\n",
    "app.layout = html.Div(\n",
    "    html.Div([\n",
    "        html.H1(children='Random nums'),\n",
    "        html.Div(children='''\n",
    "            Rand rand rand.\n",
    "        '''),\n",
    "        \n",
    "        dcc.Input(\n",
    "            id='input-y',\n",
    "            placeholder='Insert y value',\n",
    "            type='number',\n",
    "            value='',\n",
    "        ),\n",
    "        html.Div(id='result'),\n",
    "        \n",
    "        dcc.Graph(id='RandGraph',figure=dict(data=dataS,layout=layoutS))\n",
    "    ])\n",
    ")\n",
    "\n",
    "@app.callback(\n",
    "    Output('RandGraph','figure'),\n",
    "    [Input('RandGraph','relayoutData')],[State('RandGraph', 'figure')]\n",
    ")\n",
    "def update_result(relOut,Fig):\n",
    "    ymin = df.loc[relOut['xaxis.range'][1]:relOut['xaxis.range'][0],'y'].min()\n",
    "    ymax = df.loc[relOut['xaxis.range'][1]:relOut['xaxis.range'][0],'y'].max()\n",
    "    newLayout = go.Layout(\n",
    "        title=\"OL Meter\",\n",
    "        xaxis=dict(\n",
    "            rangeslider_visible=True,\n",
    "            rangeselector=dict(\n",
    "                buttons=list([\n",
    "                    dict(count=0, label=\"1m\", step=\"month\", stepmode=\"backward\"),\n",
    "                    dict(count=6, label=\"6m\", step=\"month\", stepmode=\"backward\"),\n",
    "                    dict(count=1, label=\"YTD\", step=\"year\", stepmode=\"todate\"),\n",
    "                    dict(count=1, label=\"1y\", step=\"year\", stepmode=\"backward\"),\n",
    "                    dict(count=5, label=\"5y\", step=\"year\", stepmode=\"backward\"),\n",
    "                    dict(step=\"all\")\n",
    "                ])\n",
    "            ),\n",
    "            range=relOut['xaxis.range']\n",
    "        ),\n",
    "        yaxis=dict(range=[ymin,ymax])\n",
    "    )\n",
    "    \n",
    "    \n",
    "    Fig['layout']=newLayout\n",
    "    return Fig\n",
    "\n",
    "\n",
    "\n",
    "if __name__ == '__main__':\n",
    "    app.run_server(debug=False,port=8060)"
   ]
  }
 ],
 "metadata": {
  "kernelspec": {
   "display_name": "base",
   "language": "python",
   "name": "python3"
  },
  "language_info": {
   "codemirror_mode": {
    "name": "ipython",
    "version": 3
   },
   "file_extension": ".py",
   "mimetype": "text/x-python",
   "name": "python",
   "nbconvert_exporter": "python",
   "pygments_lexer": "ipython3",
   "version": "3.11.5"
  }
 },
 "nbformat": 4,
 "nbformat_minor": 2
}
